<?xml version="1.0" ?>
<!-- =================================================================================== -->
<!-- |    This document was autogenerated by xacro from /root/colcon_ws/install/diffbot_description/share/diffbot_description/robots/diffbot.urdf.xacro | -->
<!-- |    EDITING THIS FILE BY HAND IS NOT RECOMMENDED                                 | -->
<!-- =================================================================================== -->
<!-- Basic differential drive mobile base -->
<robot name="diffbot">
  <material name="gray">
    <color rgba="0.5 0.5 0.5 1.0"/>
  </material>
  <material name="white">
    <color rgba="1.0 1.0 1.0 1.0"/>
  </material>
  <link name="base_link"/>
  <joint name="body_joint" type="fixed">
    <parent link="base_link"/>
    <child link="body_link"/>
    <origin rpy="0 0 0" xyz="-0.07 0 0.07"/>
  </joint>
  <link name="body_link">
    <inertial>
      <origin rpy="0 0 0" xyz="0 0 0"/>
      <mass value="1.0"/>
      <inertia ixx="0.001" ixy="0.0" ixz="0.0" iyy="0.001" iyz="0.0" izz="0.001"/>
    </inertial>
    <visual>
      <origin rpy="0 0 0" xyz="0 0 0"/>
      <geometry>
        <box size="0.24 0.18 0.06"/>
      </geometry>
      <material name="gray"/>
    </visual>
    <collision>
      <origin rpy="0 0 0" xyz="0 0 0"/>
      <geometry>
        <box size="0.24 0.178 0.06"/>
      </geometry>
    </collision>
  </link>
  <gazebo reference="body_link">
    <material>Gazebo/Gray</material>
  </gazebo>
  <joint name="left_wheel_joint" type="continuous">
    <origin rpy="-1.5707963267948966 0 0" xyz="0 0.1 0.05"/>
    <parent link="base_link"/>
    <child link="left_wheel_link"/>
    <axis xyz="0 0 1"/>
  </joint>
  <transmission name="left_wheel_trans" type="SimpleTransmission">
    <type>transmission_interface/SimpleTransmission</type>
    <actuator name="left_wheel_motor">
      <mechanicalReduction>50</mechanicalReduction>
    </actuator>
    <joint name="left_wheel_joint">
      <hardwareInterface>hardware_interface/VelocityJointInterface</hardwareInterface>
    </joint>
  </transmission>
  <link name="left_wheel_link">
    <inertial>
      <origin rpy="0 0 0" xyz="0 0 0"/>
      <mass value="0.1"/>
      <inertia ixx="0.0001" ixy="0.0" ixz="0.0" iyy="0.0001" iyz="0.0" izz="0.0001"/>
    </inertial>
    <visual>
      <geometry>
        <cylinder length="0.02" radius="0.05"/>
      </geometry>
      <material name="gray"/>
    </visual>
    <collision>
      <geometry>
        <cylinder length="0.02" radius="0.05"/>
      </geometry>
    </collision>
  </link>
  <gazebo reference="left_wheel_link">
    <material>Gazebo/Gray</material>
    <mu1 value="2.5"/>
    <mu2 value="2.5"/>
    <kp value="50000"/>
    <kd value="10"/>
  </gazebo>
  <joint name="right_wheel_joint" type="continuous">
    <origin rpy="-1.5707963267948966 0 0" xyz="0 -0.1 0.05"/>
    <parent link="base_link"/>
    <child link="right_wheel_link"/>
    <axis xyz="0 0 1"/>
  </joint>
  <transmission name="right_wheel_trans" type="SimpleTransmission">
    <type>transmission_interface/SimpleTransmission</type>
    <actuator name="right_wheel_motor">
      <mechanicalReduction>50</mechanicalReduction>
    </actuator>
    <joint name="right_wheel_joint">
      <hardwareInterface>hardware_interface/VelocityJointInterface</hardwareInterface>
    </joint>
  </transmission>
  <link name="right_wheel_link">
    <inertial>
      <origin rpy="0 0 0" xyz="0 0 0"/>
      <mass value="0.1"/>
      <inertia ixx="0.0001" ixy="0.0" ixz="0.0" iyy="0.0001" iyz="0.0" izz="0.0001"/>
    </inertial>
    <visual>
      <geometry>
        <cylinder length="0.02" radius="0.05"/>
      </geometry>
      <material name="gray"/>
    </visual>
    <collision>
      <geometry>
        <cylinder length="0.02" radius="0.05"/>
      </geometry>
    </collision>
  </link>
  <gazebo reference="right_wheel_link">
    <material>Gazebo/Gray</material>
    <mu1 value="2.5"/>
    <mu2 value="2.5"/>
    <kp value="50000"/>
    <kd value="10"/>
  </gazebo>
  <joint name="ball_joint" type="fixed">
    <parent link="base_link"/>
    <child link="ball_link"/>
    <origin rpy="0 0 0" xyz="-0.14 0 0.04"/>
  </joint>
  <link name="ball_link">
    <visual>
      <origin rpy="0 0 0" xyz="0 0 0"/>
      <geometry>
        <sphere radius="0.04"/>
      </geometry>
      <material name="gray"/>
    </visual>
    <collision>
      <origin rpy="0 0 0" xyz="0 0 0"/>
      <geometry>
        <sphere radius="0.04"/>
      </geometry>
      <material name="gray"/>
    </collision>
  </link>
  <gazebo reference="ball_link">
    <material>Gazebo/Gray</material>
    <mu1 value="0.5"/>
    <mu2 value="0.5"/>
  </gazebo>
  <joint name="lidar_joint" type="fixed">
    <parent link="base_link"/>
    <child link="lidar_link"/>
    <origin rpy="0 0 0" xyz="0 0 0.2"/>
  </joint>
  <link name="lidar_link">
    <visual>
      <origin rpy="0 0 0" xyz="0 0 0"/>
      <geometry>
        <cylinder length="0.08" radius="0.03"/>
      </geometry>
      <material name="white"/>
    </visual>
  </link>
  <joint name="camera_joint" type="fixed">
    <parent link="base_link"/>
    <child link="camera_link"/>
    <origin rpy="0 0 0" xyz="0.05 -0.1 0.1"/>
  </joint>
  <link name="camera_link">
    <visual>
      <origin rpy="0 -1.57 0" xyz="0 0 0"/>
      <geometry>
        <cylinder length="0.01" radius="0.01"/>
      </geometry>
      <material name="white"/>
    </visual>
  </link>
  <joint name="depth_camera_joint" type="fixed">
    <parent link="base_link"/>
    <child link="depth_camera_link"/>
    <origin rpy="0 0 0" xyz="0.05 0.1 0.1"/>
  </joint>
  <link name="depth_camera_link">
    <visual>
      <origin rpy="0 -1.57 0" xyz="0 0 0"/>
      <geometry>
        <cylinder length="0.01" radius="0.01"/>
      </geometry>
      <material name="white"/>
    </visual>
  </link>
  <!-- =============== Gazebo =============== -->
  <gazebo>
    <plugin filename="gz_ros2_control-system" name="gz_ros2_control::GazeboSimROS2ControlPlugin">
      <parameters>/root/colcon_ws/install/diffbot_description/share/diffbot_description/config/diffbot_sim.yaml</parameters>
    </plugin>
    <plugin filename="ignition-gazebo-sensors-system" name="ignition::gazebo::systems::Sensors">
      <render_engine>ogre2</render_engine>
    </plugin>
  </gazebo>
  <gazebo reference="lidar_link">
    <sensor name="lidar_link" type="gpu_lidar">
      <ignition_frame_id>lidar_link</ignition_frame_id>
      <topic>scan</topic>
      <update_rate>30</update_rate>
      <lidar>
        <scan>
          <horizontal>
            <samples>2800</samples>
            <resolution>1</resolution>
            <min_angle>-3.14</min_angle>
            <max_angle>3.14</max_angle>
          </horizontal>
          <vertical>
            <samples>1</samples>
            <resolution>0.1</resolution>
            <min_angle>0.0</min_angle>
            <max_angle>0.0</max_angle>
          </vertical>
        </scan>
        <range>
          <min>0.2</min>
          <max>30.0</max>
          <resolution>0.01</resolution>
        </range>
        <frame_id>/lidar_link</frame_id>
      </lidar>
      <alwaysOn>1</alwaysOn>
      <visualize>true</visualize>
    </sensor>
  </gazebo>
  <gazebo reference="camera_link">
    <sensor name="camera_link" type="camera">
      <update_rate>10.0</update_rate>
      <always_on>true</always_on>
      <ignition_frame_id>camera_link</ignition_frame_id>
      <pose>0 0 0 0 0 0</pose>
      <topic>/image_raw</topic>
      <camera name="diff_bot_camera">
        <!--
          <triggered>true</triggered>
          <trigger_topic>/trigger</trigger_topic>
          -->
        <horizontal_fov>1.3962634</horizontal_fov>
        <image>
          <width>600</width>
          <height>600</height>
          <format>R8G8B8</format>
        </image>
        <clip>
          <near>0.02</near>
          <far>300</far>
        </clip>
      </camera>
    </sensor>
  </gazebo>
  <gazebo reference="depth_camera_link">
    <sensor name="depth_camera_link" type="depth_camera">
      <ignition_frame_id>depth_camera_link</ignition_frame_id>
      <pose>0 0 0 0 0 0</pose>
      <camera>
        <horizontal_fov>1.047</horizontal_fov>
        <image>
          <width>320</width>
          <height>240</height>
          <format>R_FLOAT32</format>
        </image>
        <clip>
          <near>0.1</near>
          <far>100</far>
        </clip>
      </camera>
      <always_on>true</always_on>
      <update_rate>10</update_rate>
      <visualize>true</visualize>
      <topic>depth_camera/image_raw</topic>
    </sensor>
  </gazebo>
  <ros2_control name="diffbot" type="system">
    <hardware>
      <!--
          <plugin>your_hardware/YourHardware</plugin>
          -->
    </hardware>
    <joint name="left_wheel_joint">
      <command_interface name="velocity">
        <param name="min">-1</param>
        <param name="max">1</param>
      </command_interface>
      <state_interface name="position"/>
      <state_interface name="velocity"/>
      <state_interface name="effort"/>
    </joint>
    <joint name="right_wheel_joint">
      <command_interface name="velocity">
        <param name="min">-1</param>
        <param name="max">1</param>
      </command_interface>
      <state_interface name="position"/>
      <state_interface name="velocity"/>
      <state_interface name="effort"/>
    </joint>
  </ros2_control>
</robot>
