<?xml version="1.0"?>
<robot xmlns:xacro="http://ros.org/wiki/xacro">

  <xacro:macro name="diffbot" params="prefix use_sim:=^|false">

  <material name="gray">
    <color rgba="0.5 0.5 0.5 0.2"/>
    <isaac_rigid_body static_friction="0.8" dynamic_friction="0.5"/>
  </material>
  <material name="ball">
    <color rgba="0.5 0.5 0.5 0.2"/>
    <isaac_rigid_body static_friction="0.0" dynamic_friction="0.0"/>
  </material>
  <material name="white">
    <color rgba="1.0 1.0 1.0 1.0"/>
    <isaac_rigid_body static_friction="1.0" dynamic_friction="1.0"/>
  </material>

  <xacro:macro name="wheel_macro" params="parent prefix xyz">
    <joint name="${prefix}_joint" type="continuous">
      <origin xyz="${xyz}" rpy="${radians(-90)} 0 0"/>
      <parent link="${parent}"/>
      <child  link="${prefix}_link"/>
      <axis xyz="0 0 1" />
      <isaac_drive_api stiffness="0" damping="30000" joint_friction="10000"/>
    </joint>
    <transmission name="${prefix}_trans" type="SimpleTransmission">
      <type>transmission_interface/SimpleTransmission</type>
        <actuator name="${prefix}_motor">
          <mechanicalReduction>50</mechanicalReduction>
        </actuator>
      <joint name="${prefix}_joint">
        <hardwareInterface>hardware_interface/VelocityJointInterface</hardwareInterface>
      </joint>
    </transmission>
    <link name="${prefix}_link">
      <inertial>
        <origin xyz="0 0 0" rpy="0 0 0"/>
        <mass value="0.1"/>
        <inertia ixx="0.0001" ixy="0.0" ixz="0.0" iyy="0.0001" iyz="0.0" izz="0.0001"/>
      </inertial>
      <visual>
        <geometry>
          <cylinder radius="0.05" length="0.02" />
        </geometry>
        <material name="gray"/>
      </visual>
      <collision>
        <geometry>
          <cylinder radius="0.05" length="0.02" />
        </geometry>
      </collision>
    </link>
  </xacro:macro> 

  <link name="base_link"/>

  <joint name="body_joint" type="fixed">
    <parent link="base_link"/>
    <child  link="body_link"/>
    <origin xyz="-0.07 0 0.07" rpy="0 0 0"/>
  </joint>
  <link name="body_link">
    <inertial>
      <origin xyz="0 0 0" rpy="0 0 0"/>
      <mass value="1.0"/>
      <inertia ixx="0.001" ixy="0.0" ixz="0.0" iyy="0.001" iyz="0.0" izz="0.001"/>
    </inertial>
    <visual>
      <origin xyz="0 0 0" rpy="0 0 0" />
      <geometry>
        <box size="0.24 0.18 0.06" />
      </geometry>
      <material name="gray" />
    </visual>
    <collision>
      <origin xyz="0 0 0" rpy="0 0 0" />
      <geometry>
        <box size="0.24 0.178 0.06" />
      </geometry>
    </collision>
  </link>

  <xacro:wheel_macro prefix="left_wheel"  parent="base_link" xyz="0 0.1 0.05"/>
  <xacro:wheel_macro prefix="right_wheel" parent="base_link" xyz="0 -0.1 0.05"/>

  <joint name="ball_joint" type="fixed">
    <parent link="base_link"/>
    <child  link="ball_link"/>
    <origin xyz="-0.14 0 0.04" rpy="0 0 0"/>
  </joint>
  <link name="ball_link">
    <visual>
      <origin xyz="0 0 0" rpy="0 0 0" />
      <geometry>
        <sphere radius="0.04" />
      </geometry>
      <material name="ball" />
    </visual>
    <collision>
      <origin xyz="0 0 0" rpy="0 0 0" />
      <geometry>
        <sphere radius="0.04" />
      </geometry>
    </collision>
  </link>
  
  <joint name="lidar_joint" type="fixed">
    <parent link="base_link"/>
    <child  link="lidar_link"/>
    <origin xyz="0 0 0.2" rpy="0 0 0"/>
  </joint>
  <link name="lidar_link">
    <!-- If visual tag is enable, lidar's ray is blocked. -->
    <!--
    <visual>
      <origin xyz="0 0 0" rpy="0 0 0" />
      <geometry>
        <cylinder radius="0.03" length="0.08" />
      </geometry>
      <material name="white" />
    </visual>
    -->
  </link>

  <joint name="camera_joint" type="fixed">
    <parent link="base_link"/>
    <child  link="camera_link"/>
    <origin xyz="0.05 -0.1 0.1" rpy="0 0 0"/>
  </joint>
  <link name="camera_link">
    <!-- If visual tag is enable, camera's view is blocked. -->
    <!--
    <visual>
      <origin xyz="0 0 0" rpy="0 -1.57 0" />
      <geometry>
        <cylinder radius="0.01" length="0.01" />
      </geometry>
      <material name="white" />
    </visual>
    -->
  </link>

  <joint name="depth_camera_joint" type="fixed">
    <parent link="base_link"/>
    <child  link="depth_camera_link"/>
    <origin xyz="0.05 0.1 0.1" rpy="0 0 0"/>
  </joint>
  <link name="depth_camera_link">
    <!-- If visual tag is enable, camera's view is blocked. -->
    <!--
    <visual>
      <origin xyz="0 0 0" rpy="0 -1.57 0" />
      <geometry>
        <cylinder radius="0.01" length="0.01" />
      </geometry>
      <material name="white" />
    </visual>
    -->
  </link>

  </xacro:macro>
</robot>
